<?xml version="1.0" ?>
<robot name="ROBOT_PROYECTO_FUNDA" xmlns:xacro="http://www.ros.org/wiki/xacro">

<xacro:include filename="$(find ROBOT_PROYECTO_FUNDA_description)/urdf/materials.xacro" />
<xacro:include filename="$(find ROBOT_PROYECTO_FUNDA_description)/urdf/ROBOT_PROYECTO_FUNDA.trans" />
<xacro:include filename="$(find ROBOT_PROYECTO_FUNDA_description)/urdf/ROBOT_PROYECTO_FUNDA.gazebo" />
<link name="base_link">
  <inertial>
    <origin xyz="-3.0643350533575795e-15 -5.81835769624857e-17 0.018608735782155033" rpy="0 0 0"/>
    <mass value="3.681210634499537"/>
    <inertia ixx="0.007055" iyy="0.007055" izz="0.012041" ixy="-0.0" iyz="-0.0" ixz="-0.0"/>
  </inertial>
  <visual>
    <origin xyz="0 0 0" rpy="0 0 0"/>
    <geometry>
      <mesh filename="package://ROBOT_PROYECTO_FUNDA_description/meshes/base_link.stl" scale="0.001 0.001 0.001"/>
    </geometry>
    <material name="silver"/>
  </visual>
  <collision>
    <origin xyz="0 0 0" rpy="0 0 0"/>
    <geometry>
      <mesh filename="package://ROBOT_PROYECTO_FUNDA_description/meshes/base_link.stl" scale="0.001 0.001 0.001"/>
    </geometry>
  </collision>
</link>

<link name="link1_1">
  <inertial>
    <origin xyz="-2.1512973629865014e-05 -4.170466759319841e-09 0.016937708587327557" rpy="0 0 0"/>
    <mass value="2.3854069792520733"/>
    <inertia ixx="0.002223" iyy="0.002484" izz="0.002413" ixy="-0.0" iyz="-0.0" ixz="2e-06"/>
  </inertial>
  <visual>
    <origin xyz="-0.0 -0.0 -0.05" rpy="0 0 0"/>
    <geometry>
      <mesh filename="package://ROBOT_PROYECTO_FUNDA_description/meshes/link1_1.stl" scale="0.001 0.001 0.001"/>
    </geometry>
    <material name="silver"/>
  </visual>
  <collision>
    <origin xyz="-0.0 -0.0 -0.05" rpy="0 0 0"/>
    <geometry>
      <mesh filename="package://ROBOT_PROYECTO_FUNDA_description/meshes/link1_1.stl" scale="0.001 0.001 0.001"/>
    </geometry>
  </collision>
</link>

<link name="link2_1">
  <inertial>
    <origin xyz="5.03801001463613e-10 -0.002257669022233806 0.13383977677365372" rpy="0 0 0"/>
    <mass value="2.0825690848458756"/>
    <inertia ixx="0.009789" iyy="0.010731" izz="0.001784" ixy="0.0" iyz="0.000234" ixz="-0.0"/>
  </inertial>
  <visual>
    <origin xyz="0.0 -0.0 -0.106" rpy="0 0 0"/>
    <geometry>
      <mesh filename="package://ROBOT_PROYECTO_FUNDA_description/meshes/link2_1.stl" scale="0.001 0.001 0.001"/>
    </geometry>
    <material name="silver"/>
  </visual>
  <collision>
    <origin xyz="0.0 -0.0 -0.106" rpy="0 0 0"/>
    <geometry>
      <mesh filename="package://ROBOT_PROYECTO_FUNDA_description/meshes/link2_1.stl" scale="0.001 0.001 0.001"/>
    </geometry>
  </collision>
</link>

<link name="link3_1">
  <inertial>
    <origin xyz="-3.551362869946606e-19 0.00434317057470694 0.015475703131377472" rpy="0 0 0"/>
    <mass value="0.17175014190624968"/>
    <inertia ixx="0.000112" iyy="0.000112" izz="6.3e-05" ixy="-0.0" iyz="-2e-06" ixz="-0.0"/>
  </inertial>
  <visual>
    <origin xyz="-0.0 0.005 -0.301" rpy="0 0 0"/>
    <geometry>
      <mesh filename="package://ROBOT_PROYECTO_FUNDA_description/meshes/link3_1.stl" scale="0.001 0.001 0.001"/>
    </geometry>
    <material name="silver"/>
  </visual>
  <collision>
    <origin xyz="-0.0 0.005 -0.301" rpy="0 0 0"/>
    <geometry>
      <mesh filename="package://ROBOT_PROYECTO_FUNDA_description/meshes/link3_1.stl" scale="0.001 0.001 0.001"/>
    </geometry>
  </collision>
</link>

<link name="link4_1">
  <inertial>
    <origin xyz="0.010683265864992925 0.1217611875039267 -5.493222942482001e-05" rpy="0 0 0"/>
    <mass value="1.1883665556027"/>
    <inertia ixx="0.004412" iyy="0.000734" izz="0.004962" ixy="-0.000714" iyz="4e-06" ixz="2e-06"/>
  </inertial>
  <visual>
    <origin xyz="-0.0 -0.025 -0.328" rpy="0 0 0"/>
    <geometry>
      <mesh filename="package://ROBOT_PROYECTO_FUNDA_description/meshes/link4_1.stl" scale="0.001 0.001 0.001"/>
    </geometry>
    <material name="silver"/>
  </visual>
  <collision>
    <origin xyz="-0.0 -0.025 -0.328" rpy="0 0 0"/>
    <geometry>
      <mesh filename="package://ROBOT_PROYECTO_FUNDA_description/meshes/link4_1.stl" scale="0.001 0.001 0.001"/>
    </geometry>
  </collision>
</link>

<link name="link5_1">
  <inertial>
    <origin xyz="2.7841458772332624e-09 -0.005581416777431569 5.137388451065261e-05" rpy="0 0 0"/>
    <mass value="0.025978846048009454"/>
    <inertia ixx="6e-06" iyy="2e-06" izz="6e-06" ixy="-0.0" iyz="-0.0" ixz="-0.0"/>
  </inertial>
  <visual>
    <origin xyz="-0.0 -0.203 -0.327766" rpy="0 0 0"/>
    <geometry>
      <mesh filename="package://ROBOT_PROYECTO_FUNDA_description/meshes/link5_1.stl" scale="0.001 0.001 0.001"/>
    </geometry>
    <material name="silver"/>
  </visual>
  <collision>
    <origin xyz="-0.0 -0.203 -0.327766" rpy="0 0 0"/>
    <geometry>
      <mesh filename="package://ROBOT_PROYECTO_FUNDA_description/meshes/link5_1.stl" scale="0.001 0.001 0.001"/>
    </geometry>
  </collision>
</link>

<link name="link6_1">
  <inertial>
    <origin xyz="-3.2260852801792407e-07 0.014664378789435384 -1.155322028711936e-06" rpy="0 0 0"/>
    <mass value="0.15787075091036468"/>
    <inertia ixx="2.1e-05" iyy="1.7e-05" izz="2.1e-05" ixy="0.0" iyz="0.0" ixz="0.0"/>
  </inertial>
  <visual>
    <origin xyz="-0.0 -0.228 -0.328" rpy="0 0 0"/>
    <geometry>
      <mesh filename="package://ROBOT_PROYECTO_FUNDA_description/meshes/link6_1.stl" scale="0.001 0.001 0.001"/>
    </geometry>
    <material name="silver"/>
  </visual>
  <collision>
    <origin xyz="-0.0 -0.228 -0.328" rpy="0 0 0"/>
    <geometry>
      <mesh filename="package://ROBOT_PROYECTO_FUNDA_description/meshes/link6_1.stl" scale="0.001 0.001 0.001"/>
    </geometry>
  </collision>
</link>

<joint name="Revolución 1" type="revolute">
  <origin xyz="0.0 0.0 0.05" rpy="0 0 0"/>
  <parent link="base_link"/>
  <child link="link1_1"/>
  <axis xyz="0.0 0.0 1.0"/>
  <limit upper="6.283185" lower="0.0" effort="100" velocity="100"/>
</joint>

<joint name="Revolución 2" type="revolute">
  <origin xyz="-0.0 0.0 0.056" rpy="0 0 0"/>
  <parent link="link1_1"/>
  <child link="link2_1"/>
  <axis xyz="1.0 0.0 0.0"/>
  <limit upper="1.570796" lower="-1.570796" effort="100" velocity="100"/>
</joint>

<joint name="Revolución 4" type="revolute">
  <origin xyz="0.0 -0.005 0.195" rpy="0 0 0"/>
  <parent link="link2_1"/>
  <child link="link3_1"/>
  <axis xyz="1.0 0.0 0.0"/>
  <limit upper="1.570796" lower="-1.570796" effort="100" velocity="100"/>
</joint>

<joint name="Revolución 5" type="revolute">
  <origin xyz="0.0 0.03 0.027" rpy="0 0 0"/>
  <parent link="link3_1"/>
  <child link="link4_1"/>
  <axis xyz="0.0 1.0 0.0"/>
  <limit upper="6.283185" lower="0.0" effort="100" velocity="100"/>
</joint>

<joint name="Revolución 6" type="revolute">
  <origin xyz="0.0 0.178 -0.000234" rpy="0 0 0"/>
  <parent link="link4_1"/>
  <child link="link5_1"/>
  <axis xyz="-1.0 0.0 0.0"/>
  <limit upper="1.570796" lower="-1.570796" effort="100" velocity="100"/>
</joint>

<joint name="Revolución 7" type="revolute">
  <origin xyz="0.0 0.025 0.000234" rpy="0 0 0"/>
  <parent link="link5_1"/>
  <child link="link6_1"/>
  <axis xyz="0.0 1.0 0.0"/>
  <limit upper="6.283185" lower="0.0" effort="100" velocity="100"/>
</joint>

</robot>
